<?xml version="1.0" encoding="utf-8"?>
<!-- This URDF was automatically created by SolidWorks to URDF Exporter! Originally created by Stephen Brawner (brawner@gmail.com) 
     Commit Version: 1.6.0-4-g7f85cfe  Build Version: 1.6.7995.38578
     For more information, please see http://wiki.ros.org/sw_urdf_exporter -->
<robot
  name="car_urdf">
  
  
  <link name="world"/>
  <joint name="base_joint" type="fixed">
  	<parent link="world"/>
  	<child link="base_link"/>
  	<origin rpy="0 0 0" xyz="0.0 0.0 0.17"/>
  </joint>
  
  
  
  
  
  
  <link
    name="base_link">
    <inertial>
      <origin
        xyz="0.0026780293823337 -8.36143291757518E-08 0.0290503422675615"
        rpy="0 0 0" />
      <mass
        value="7.27297177380424" />
      <inertia
        ixx="0.00718750082613249"
        ixy="2.93108378932942E-08"
        ixz="0.000183481880866288"
        iyy="0.0213063434769695"
        iyz="3.17408145828072E-09"
        izz="0.024330713862357" />
    </inertial>
    <visual>
      <origin
        xyz="0 0 0"
        rpy="0 0 0" />
      <geometry>
        <mesh
          filename="package://car_urdf/meshes/base_link.STL" />
      </geometry>
      <material
        name="">
        <color
          rgba="0.317647058823529 0.247058823529412 0.207843137254902 1" />
      </material>
    </visual>
    <collision>
      <origin
        xyz="0 0 0"
        rpy="0 0 0" />
      <geometry>
        <mesh
          filename="package://car_urdf/meshes/base_link.STL" />
      </geometry>
    </collision>
  </link>
  
  
  
  
  
  
  
  
  <link
    name="fl_pin">
    <inertial>
      <origin
        xyz="0 0 0"
        rpy="0 0 0" />
      <mass
        value="0.0023308440408083" />
      <inertia
        ixx="1.46454208894841E-07"
        ixy="-6.18313709918053E-17"
        ixz="9.89467996740187E-15"
        iyy="1.47741105823912E-07"
        iyz="-3.48879471398126E-15"
        izz="9.49179293760492E-08" />
    </inertial>
    <visual>
      <origin
        xyz="0 0 0"
        rpy="0 0 0" />
      <geometry>
        <mesh
          filename="package://car_urdf/meshes/fl_pin.STL" />
      </geometry>
      <material
        name="">
        <color
          rgba="0.792156862745098 0.819607843137255 0.933333333333333 1" />
      </material>
    </visual>
    <collision>
      <origin
        xyz="0 0 0"
        rpy="0 0 0" />
      <geometry>
        <mesh
          filename="package://car_urdf/meshes/fl_pin.STL" />
      </geometry>
    </collision>
  </link>
  <joint
    name="fl_pin_j"
    type="revolute">
    <origin
      xyz="0 0 0"
      rpy="0 0 0" />
    <parent
      link="base_link" />
    <child
      link="fl_pin" />
    <axis
      xyz="0 0 -1" />
    <limit
      lower="-0.6"
      upper="0.6"
      effort="0"
      velocity="0" />
  </joint>
  <link
    name="fl_wheel">
    <inertial>
      <origin
        xyz="1.3878E-17 0.0014286 0"
        rpy="0 0 0" />
      <mass
        value="0.010996" />
      <inertia
        ixx="1.0608E-06"
        ixy="2.9156E-23"
        ixz="-1.1484E-22"
        iyy="1.4334E-06"
        iyz="-3.7952E-24"
        izz="1.0608E-06" />
    </inertial>
    <visual>
      <origin
        xyz="0 0 0"
        rpy="0 0 0" />
      <geometry>
        <mesh
          filename="package://car_urdf/meshes/fl_wheel.STL" />
      </geometry>
      <material
        name="">
        <color
          rgba="0.79216 0.81961 0.93333 1" />
      </material>
    </visual>
    <collision>
      <origin
        xyz="0 0 0"
        rpy="0 0 0" />
      <geometry>
        <mesh
          filename="package://car_urdf/meshes/fl_wheel.STL" />
      </geometry>
    </collision>
  </link>
  <joint
    name="fl_wheeel_j"
    type="continuous">
    <origin
      xyz="0 0.005 -0.004"
      rpy="0 0 0" />
    <parent
      link="fl_pin" />
    <child
      link="fl_wheel" />
    <axis
      xyz="0 1 0" />
    <limit
      lower="0"
      upper="0"
      effort="0"
      velocity="0" />
  </joint>
  <link
    name="fr_pin">
    <inertial>
      <origin
        xyz="1.00167027450304E-11 0.00242832295403607 -0.00399999920262951"
        rpy="0 0 0" />
      <mass
        value="0.0023308440408083" />
      <inertia
        ixx="1.46454208894841E-07"
        ixy="6.18313535787126E-17"
        ixz="-9.89467996779412E-15"
        iyy="1.47741105823912E-07"
        iyz="-3.488794709453E-15"
        izz="9.49179293760492E-08" />
    </inertial>
    <visual>
      <origin
        xyz="0 0 0"
        rpy="0 0 0" />
      <geometry>
        <mesh
          filename="package://car_urdf/meshes/fr_pin.STL" />
      </geometry>
      <material
        name="">
        <color
          rgba="0.792156862745098 0.819607843137255 0.933333333333333 1" />
      </material>
    </visual>
    <collision>
      <origin
        xyz="0 0 0"
        rpy="0 0 0" />
      <geometry>
        <mesh
          filename="package://car_urdf/meshes/fr_pin.STL" />
      </geometry>
    </collision>
  </link>
  <joint
    name="fr_pin_j"
    type="revolute">
    <origin
      xyz="0.065223 -0.045 0.004"
      rpy="0 0 0" />
    <parent
      link="base_link" />
    <child
      link="fr_pin" />
    <axis
      xyz="0 0 -1" />
    <limit
      lower="-0.6"
      upper="0.6"
      effort="0"
      velocity="0" />
  </joint>
  <link
    name="fr_wheel">
    <inertial>
      <origin
        xyz="-6.9389E-18 -0.0014286 0"
        rpy="0 0 0" />
      <mass
        value="0.010996" />
      <inertia
        ixx="1.0608E-06"
        ixy="8.2862E-23"
        ixz="1.3852E-22"
        iyy="1.4334E-06"
        iyz="-2.4914E-23"
        izz="1.0608E-06" />
    </inertial>
    <visual>
      <origin
        xyz="0 0 0"
        rpy="0 0 0" />
      <geometry>
        <mesh
          filename="package://car_urdf/meshes/fr_wheel.STL" />
      </geometry>
      <material
        name="">
        <color
          rgba="0.79216 0.81961 0.93333 1" />
      </material>
    </visual>
    <collision>
      <origin
        xyz="0 0 0"
        rpy="0 0 0" />
      <geometry>
        <mesh
          filename="package://car_urdf/meshes/fr_wheel.STL" />
      </geometry>
    </collision>
  </link>
  <joint
    name="fr_wheel_j"
    type="continuous">
    <origin
      xyz="0 -0.005 -0.004"
      rpy="0 0 0" />
    <parent
      link="fr_pin" />
    <child
      link="fr_wheel" />
    <axis
      xyz="0 -1 0" />
  </joint>
  <link
    name="rl_wheel">
    <inertial>
      <origin
        xyz="1.5821E-15 0.018333 5.6899E-16"
        rpy="0 0 0" />
      <mass
        value="0.015904" />
      <inertia
        ixx="1.6595E-06"
        ixy="-4.2486E-20"
        ixz="-5.2716E-23"
        iyy="1.6401E-06"
        iyz="-1.4995E-20"
        izz="1.6595E-06" />
    </inertial>
    <visual>
      <origin
        xyz="0 0 0"
        rpy="0 0 0" />
      <geometry>
        <mesh
          filename="package://car_urdf/meshes/rl_wheel.STL" />
      </geometry>
      <material
        name="">
        <color
          rgba="0.79216 0.81961 0.93333 1" />
      </material>
    </visual>
    <collision>
      <origin
        xyz="0 0 0"
        rpy="0 0 0" />
      <geometry>
        <mesh
          filename="package://car_urdf/meshes/rl_wheel.STL" />
      </geometry>
    </collision>
  </link>
  <joint
    name="rl_wheel_j"
    type="continuous">
    <origin
      xyz="-0.054777 0.03 0"
      rpy="0 0 0" />
    <parent
      link="base_link" />
    <child
      link="rl_wheel" />
    <axis
      xyz="0 -1 0" />
  </joint>
  <link
    name="rr_wheel">
    <inertial>
      <origin
        xyz="0 -0.018333 0"
        rpy="0 0 0" />
      <mass
        value="0" />
      <inertia
        ixx="0"
        ixy="0"
        ixz="0"
        iyy="0"
        iyz="0"
        izz="0" />
    </inertial>
    <visual>
      <origin
        xyz="0 0 0"
        rpy="0 0 0" />
      <geometry>
        <mesh
          filename="package://car_urdf/meshes/rr_wheel.STL" />
      </geometry>
      <material
        name="">
        <color
          rgba="1 1 1 1" />
      </material>
    </visual>
    <collision>
      <origin
        xyz="0 0 0"
        rpy="0 0 0" />
      <geometry>
        <mesh
          filename="package://car_urdf/meshes/rr_wheel.STL" />
      </geometry>
    </collision>
  </link>
  <joint
    name="rr_wheel_j"
    type="continuous">
    <origin
      xyz="-0.054777 -0.03 0"
      rpy="0 0 0" />
    <parent
      link="base_link" />
    <child
      link="rr_wheel" />
    <axis
      xyz="0 1 0" />
  </joint>
  
  
  
  
  
  
  
  
  
  
  <!-- Ackermann drive plugin -->
  <gazebo>
    <plugin name="gazebo_ros_ackermann_drive" filename="libgazebo_ros_ackermann_drive.so">
      <ros>
        <namespace>/</namespace>
        <remapping>cmd_vel:=cmd_vel</remapping>
        <remapping>odom:=odom</remapping>
        <remapping>distance:=distance</remapping>
      </ros>

      <update_rate>100.0</update_rate>

      <!-- Joint names -->
      <front_left_joint>fl_wheel_joint</front_left_joint>
      <front_right_joint>fr_wheel_joint</front_right_joint>
      <rear_left_joint>rl_wheel_joint</rear_left_joint>
      <rear_right_joint>rr_wheel_joint</rear_right_joint>
      <left_steering_joint>fl_steering_joint</left_steering_joint>
      <right_steering_joint>fr_steering_joint</right_steering_joint>

      <!-- Limits -->
      <max_steer>0.6</max_steer>
      <max_speed>20</max_speed>

      <!-- PID Controllers -->
      <left_steering_pid_gain>1500 0 1</left_steering_pid_gain>
      <right_steering_pid_gain>1500 0 1</right_steering_pid_gain>
      <linear_velocity_pid_gain>1000 0 1</linear_velocity_pid_gain>

      <!-- Publishing options -->
      <publish_odom>true</publish_odom>
      <publish_odom_tf>true</publish_odom_tf>
      <publish_wheel_tf>true</publish_wheel_tf>
      <publish_distance>true</publish_distance>

      <odometry_frame>odom</odometry_frame>
      <robot_base_frame>base_link</robot_base_frame>
    </plugin>
    
    
    
  </gazebo>

  <!-- Material colors for Gazebo -->
  <gazebo reference="base_link">
    <material>Gazebo/Brown</material>
  </gazebo>

  <gazebo reference="fl_pin">
    <material>Gazebo/Gray</material>
  </gazebo>

  <gazebo reference="fr_pin">
    <material>Gazebo/Gray</material>
  </gazebo>

  <gazebo reference="fl_wheel">
    <material>Gazebo/Gray</material>
  </gazebo>

  <gazebo reference="fr_wheel">
    <material>Gazebo/Gray</material>
  </gazebo>

  <gazebo reference="rl_wheel">
    <material>Gazebo/Gray</material>
  </gazebo>

  <gazebo reference="rr_wheel">
    <material>Gazebo/Gray</material>
  </gazebo>
  
  
  
  
</robot>
